Workbook

Sheet Rules_and_Assumptions
A1: High-Value Merchant Day — exact classification rule
A3: A transaction on Sheet1 is labeled "High-Value Merchant Day" (column L) when BOTH:
A4: 1. That merchant's total CAPTURED amount_inr on that calendar date exceeds INR 5,000 (strictly greater than — 5,000 itself does not qualify).
A5: 2. That merchant's region (from Merchant_Region_Map) is NOT "East".
A7: Formula (Sheet1!L2): =IF(AND(J2>5000,K2<>"East"),"High-Value Merchant Day","")
A9: How each input is computed:
A10: • Column I (txn_date) = INT(transaction_time) — strips the time-of-day so transactions are grouped by calendar date.
A11: • Column J (merchant_daily_total_captured_inr) is looked up via INDEX/MATCH from the Daily_Merchant_Pivot sheet, a pivot-style
A12: summary (Sum of amount_inr, rows = date, columns = merchant_id) built with SUMIFS, restricted to status = "captured".
A13: • Column K (merchant_region) is looked up via INDEX/MATCH from Merchant_Region_Map (merchant_id → region).
A15: Judgment calls made (documented per the workbook's requirement to state any distinct rule explicitly):
A16: 1. STATUS FILTER — the daily total includes only status = "captured" transactions, not "failed" or "chargeback", on the
... A31: • Merchant_Region_Map — merchant_id → merchant_name / category / region reference, sourced from merchant_workbook.ods.

Sheet Master
A1: transaction_id | B1: user_id | C1: merchant_id | D1: merchant_name | E1: transaction_time | F1: amount_inr | G1: payment_method | H1: status | I1: risk_score | J1: txn_date | K1: merchant_daily_total_captured_inr | L1: merchant_region | M1: classification
A2: TXN100000 | B2: 350 | C2: 16 | D2: =IFERROR(VLOOKUP(C2,[1]Sheet1!$A$1:$C$41,2,0),"Merchant Not Found") -> Merchant_016 | E2: 46051.467 | F2: 2999 | H2: captured | I2: 85 | J2: =INT(E2) -> 46051 | K2: =INDEX(Daily_Merchant_Pivot!$B$3:$AO$32,MATCH(J2,Daily_Merchant_Pivot!$A$3:$A$32,0),MATCH(C2,Daily_Merchant_Pivot!$B$2:$AO$2,0)) -> 0 | L2: West | M2: =IF(AND(K2>5000,L2<>"East"),"High-Value Merchant Day","")
A3: TXN100001 | B3: 287 | C3: 27 | D3: =IFERROR(VLOOKUP(C3,[1]Sheet1!$A$1:$C$41,2,0),"Merchant Not Found") -> Merchant_027 | E3: 46026.492 | F3: 49 | G3: UPI | H3: captured | I3: 79 | J3: =INT(E3) -> 46026 | K3: =INDEX(Daily_Merchant_Pivot!$B$3:$AO$32,MATCH(J3,Daily_Merchant_Pivot!$A$3:$A$32,0),MATCH(C3,Daily_Merchant_Pivot!$B$2:$AO$2,0)) -> 49 | L3: =INDEX(Merchant_Region_Map!$D$3:$D$42,MATCH(C3,Merchant_Region_Map!$A$3:$A$42,0)) -> North | M3: =IF(AND(K3>5000,L3<>"East"),"High-Value Merchant Day","")
A4: TXN100002 | B4: 122 | C4: 11 | D4: =IFERROR(VLOOKUP(C4,[1]Sheet1!$A$1:$C$41,2,0),"Merchant Not Found") -> Merchant_011 | E4: 46046.208 | F4: 1499 | G4: Wallet | H4: captured | I4: 22 | J4: =INT(E4) -> 46046 | K4: =INDEX(Daily_Merchant_Pivot!$B$3:$AO$32,MATCH(J4,Daily_Merchant_Pivot!$A$3:$A$32,0),MATCH(C4,Daily_Merchant_Pivot!$B$2:$AO$2,0)) -> 1798 | L4: =INDEX(Merchant_Region_Map!$D$3:$D$42,MATCH(C4,Merchant_Region_Map!$A$3:$A$42,0)) -> North | M4: =IF(AND(K4>5000,L4<>"East"),"High-Value Merchant Day","")
A5: TXN100003 | B5: 92 | C5: 22 | D5: =IFERROR(VLOOKUP(C5,[1]Sheet1!$A$1:$C$41,2,0),"Merchant Not Found") -> Merchant_022 | E5: 46051.542 | F5: 49 | G5: Netbanking | H5: captured | I5: 100 | J5: =INT(E5) -> 46051 | K5: =INDEX(Daily_Merchant_Pivot!$B$3:$AO$32,MATCH(J5,Daily_Merchant_Pivot!$A$3:$A$32,0),MATCH(C5,Daily_Merchant_Pivot!$B$2:$AO$2,0)) -> 49 | L5: =INDEX(Merchant_Region_Map!$D$3:$D$42,MATCH(C5,Merchant_Region_Map!$A$3:$A$42,0)) -> South | M5: =IF(AND(K5>5000,L5<>"East"),"High-Value Merchant Day","")
A6: TXN100004 | B6: 343 | C6: 16 | D6: =IFERROR(VLOOKUP(C6,[1]Sheet1!$A$1:$C$41,2,0),"Merchant Not Found") -> Merchant_016 | E6: 46052.577 | F6: 99 | G6: UPI | H6: captured | I6: 34 | J6: =INT(E6) -> 46052 | K6: =INDEX(Daily_Merchant_Pivot!$B$3:$AO$32,MATCH(J6,Daily_Merchant_Pivot!$A$3:$A$32,0),MATCH(C6,Daily_Merchant_Pivot!$B$2:$AO$2,0)) -> 898 | L6: =INDEX(Merchant_Region_Map!$D$3:$D$42,MATCH(C6,Merchant_Region_Map!$A$3:$A$42,0)) -> West | M6: =IF(AND(K6>5000,L6<>"East"),"High-Value Merchant Day","")
A7: TXN100006 | B7: 236 | C7: 23 | D7: =IFERROR(VLOOKUP(C7,[1]Sheet1!$A$1:$C$41,2,0),"Merchant Not Found") -> Merchant_023 | E7: 46030.286 | F7: 99 | G7: Wallet | H7: captured | I7: 39 | J7: =INT(E7) -> 46030 | K7: =INDEX(Daily_Merchant_Pivot!$B$3:$AO$32,MATCH(J7,Daily_Merchant_Pivot!$A$3:$A$32,0),MATCH(C7,Daily_Merchant_Pivot!$B$2:$AO$2,0)) -> 99 | L7: =INDEX(Merchant_Region_Map!$D$3:$D$42,MATCH(C7,Merchant_Region_Map!$A$3:$A$42,0)) -> North | M7: =IF(AND(K7>5000,L7<>"East"),"High-Value Merchant Day","")
A8: TXN100007 | B8: 13 | C8: 13 | D8: =IFERROR(VLOOKUP(C8,[1]Sheet1!$A$1:$C$41,2,0),"Merchant Not Found") -> Merchant_013 | E8: 46049.301 | F8: 99 | G8: UPI | H8: captured | I8: 51 | J8: =INT(E8) -> 46049 | K8: =INDEX(Daily_Merchant_Pivot!$B$3:$AO$32,MATCH(J8,Daily_Merchant_Pivot!$A$3:$A$32,0),MATCH(C8,Daily_Merchant_Pivot!$B$2:$AO$2,0)) -> 1598 | L8: =INDEX(Merchant_Region_Map!$D$3:$D$42,MATCH(C8,Merchant_Region_Map!$A$3:$A$42,0)) -> East | M8: =IF(AND(K8>5000,L8<>"East"),"High-Value Merchant Day","")
A9: TXN100008 | B9: 36 | C9: 18 | D9: =IFERROR(VLOOKUP(C9,[1]Sheet1!$A$1:$C$41,2,0),"Merchant Not Found") -> Merchant_018 | E9: 46033.372 | F9: 799 | G9: UPI | H9: captured | I9: 44 | J9: =INT(E9) -> 46033 | K9: =INDEX(Daily_Merchant_Pivot!$B$3:$AO$32,MATCH(J9,Daily_Merchant_Pivot!$A$3:$A$32,0),MATCH(C9,Daily_Merchant_Pivot!$B$2:$AO$2,0)) -> 799 | L9: =INDEX(Merchant_Region_Map!$D$3:$D$42,MATCH(C9,Merchant_Region_Map!$A$3:$A$42,0)) -> West | M9: =IF(AND(K9>5000,L9<>"East"),"High-Value Merchant Day","")
A10: TXN100009 | B10: 348 | C10: 35 | D10: =IFERROR(VLOOKUP(C10,[1]Sheet1!$A$1:$C$41,2,0),"Merchant Not Found") -> Merchant_035 | E10: 46043.684 | F10: 299 | G10: UPI | H10: captured | I10: 42 | J10: =INT(E10) -> 46043 | K10: =INDEX(Daily_Merchant_Pivot!$B$3:$AO$32,MATCH(J10,Daily_Merchant_Pivot!$A$3:$A$32,0),MATCH(C10,Daily_Merchant_Pivot!$B$2:$AO$2,0)) -> 299 | L10: =INDEX(Merchant_Region_Map!$D$3:$D$42,MATCH(C10,Merchant_Region_Map!$A$3:$A$42,0)) -> East | M10: =IF(AND(K10>5000,L10<>"East"),"High-Value Merchant Day","")
A11: TXN100010 | B11: 134 | C11: 12 | D11: =IFERROR(VLOOKUP(C11,[1]Sheet1!$A$1:$C$41,2,0),"Merchant Not Found") -> Merchant_012 | E11: 46023.164 | F11: 49 | G11: UPI | H11: captured | I11: 74 | J11: =INT(E11) -> 46023 | K11: =INDEX(Daily_Merchant_Pivot!$B$3:$AO$32,MATCH(J11,Daily_Merchant_Pivot!$A$3:$A$32,0),MATCH(C11,Daily_Merchant_Pivot!$B$2:$AO$2,0)) -> 548 | L11: =INDEX(Merchant_Region_Map!$D$3:$D$42,MATCH(C11,Merchant_Region_Map!$A$3:$A$42,0)) -> East | M11: =IF(AND(K11>5000,L11<>"East"),"High-Value Merchant Day","")
A12: TXN100011 | B12: 306 | C12: 28 | D12: =IFERROR(VLOOKUP(C12,[1]Sheet1!$A$1:$C$41,2,0),"Merchant Not Found") -> Merchant_028 | E12: 46031.046 | F12: 2949 | G12: Card | H12: failed | I12: 44 | J12: =INT(E12) -> 46031 | K12: =INDEX(Daily_Merchant_Pivot!$B$3:$AO$32,MATCH(J12,Daily_Merchant_Pivot!$A$3:$A$32,0),MATCH(C12,Daily_Merchant_Pivot!$B$2:$AO$2,0)) -> 0 | L12: =INDEX(Merchant_Region_Map!$D$3:$D$42,MATCH(C12,Merchant_Region_Map!$A$3:$A$42,0)) -> South | M12: =IF(AND(K12>5000,L12<>"East"),"High-Value Merchant Day","")
A13: TXN100012 | B13: 311 | C13: 33 | D13: =IFERROR(VLOOKUP(C13,[1]Sheet1!$A$1:$C$41,2,0),"Merchant Not Found") -> Merchant_033 | E13: 46046.435 | F13: 49 | G13: Wallet | H13: captured | I13: 14 | J13: =INT(E13) -> 46046 | K13: =INDEX(Daily_Merchant_Pivot!$B$3:$AO$32,MATCH(J13,Daily_Merchant_Pivot!$A$3:$A$32,0),MATCH(C13,Daily_Merchant_Pivot!$B$2:$AO$2,0)) -> 49 | L13: =INDEX(Merchant_Region_Map!$D$3:$D$42,MATCH(C13,Merchant_Region_Map!$A$3:$A$42,0)) -> East | M13: =IF(AND(K13>5000,L13<>"East"),"High-Value Merchant Day","")
A14: TXN100013 | B14: 131 | C14: 3 | D14: =IFERROR(VLOOKUP(C14,[1]Sheet1!$A$1:$C$41,2,0),"Merchant Not Found") -> Merchant_003 | E14: 46035.758 | F14: 49 | G14: UPI | H14: captured | I14: 90 | J14: =INT(E14) -> 46035 | K14: =INDEX(Daily_Merchant_Pivot!$B$3:$AO$32,MATCH(J14,Daily_Merchant_Pivot!$A$3:$A$32,0),MATCH(C14,Daily_Merchant_Pivot!$B$2:$AO$2,0)) -> 49 | L14: =INDEX(Merchant_Region_Map!$D$3:$D$42,MATCH(C14,Merchant_Region_Map!$A$3:$A$42,0)) -> East | M14: =IF(AND(K14>5000,L14<>"East"),"High-Value Merchant Day","")
... A532: TXNX9009 | B532: 59 | C532: 18 | D532: =IFERROR(VLOOKUP(C532,[1]Sheet1!$A$1:$C$41,2,0),"Merchant Not Found") -> Merchant_018 | E532: 46047 | F532: 4999 | G532: Card | H532: captured | I532: 69 | J532: =INT(E532) -> 46047 | K532: =INDEX(Daily_Merchant_Pivot!$B$3:$AO$32,MATCH(J532,Daily_Merchant_Pivot!$A$3:$A$32,0),MATCH(C532,Daily_Merchant_Pivot!$B$2:$AO$2,0)) -> 6647 | L532: =INDEX(Merchant_Region_Map!$D$3:$D$42,MATCH(C532,Merchant_Region_Map!$A$3:$A$42,0)) -> West | M532: =IF(AND(K532>5000,L532<>"East"),"High-Value Merchant Day","") -> High-Value Merchant Day
D533: =IFERROR(VLOOKUP(C533,[1]Sheet1!$A$1:$C$41,2,0),"Merchant Not Found") -> Merchant Not Found
D534: =IFERROR(VLOOKUP(C534,[1]Sheet1!$A$1:$C$41,2,0),"Merchant Not Found") -> Merchant Not Found
D535: =IFERROR(VLOOKUP(C535,[1]Sheet1!$A$1:$C$41,2,0),"Merchant Not Found") -> Merchant Not Found
D536: =IFERROR(VLOOKUP(C536,[1]Sheet1!$A$1:$C$41,2,0),"Merchant Not Found") -> Merchant Not Found
D537: =IFERROR(VLOOKUP(C537,[1]Sheet1!$A$1:$C$41,2,0),"Merchant Not Found") -> Merchant Not Found
D538: =IFERROR(VLOOKUP(C538,[1]Sheet1!$A$1:$C$41,2,0),"Merchant Not Found") -> Merchant Not Found
D539: =IFERROR(VLOOKUP(C539,[1]Sheet1!$A$1:$C$41,2,0),"Merchant Not Found") -> Merchant Not Found
D540: =IFERROR(VLOOKUP(C540,[1]Sheet1!$A$1:$C$41,2,0),"Merchant Not Found") -> Merchant Not Found
D541: =IFERROR(VLOOKUP(C541,[1]Sheet1!$A$1:$C$41,2,0),"Merchant Not Found") -> Merchant Not Found
D542: =IFERROR(VLOOKUP(C542,[1]Sheet1!$A$1:$C$41,2,0),"Merchant Not Found") -> Merchant Not Found
D543: =IFERROR(VLOOKUP(C543,[1]Sheet1!$A$1:$C$41,2,0),"Merchant Not Found") -> Merchant Not Found
D544: =IFERROR(VLOOKUP(C544,[1]Sheet1!$A$1:$C$41,2,0),"Merchant Not Found") -> Merchant Not Found
... D549: =IFERROR(VLOOKUP(C549,[1]Sheet1!$A$1:$C$41,2,0),"Merchant Not Found") -> Merchant Not Found

Sheet Merchant_Region_Map
A1: Source: merchant_workbook.ods, sheet "Sheet1" (transaction-level export with merchant attributes), deduplicated to one row per merchant_id.
A2: merchant_id | B2: merchant_name | C2: category | D2: region
A3: 1 | B3: Merchant_001 | C3: ecommerce | D3: South
A4: 2 | B4: Merchant_002 | C4: grocery | D4: West
A5: 3 | B5: Merchant_003 | C5: grocery | D5: East
A6: 4 | B6: Merchant_004 | C6: ecommerce | D6: East
A7: 5 | B7: Merchant_005 | C7: recharge | D7: South
A8: 6 | B8: Merchant_006 | C8: food_delivery | D8: South
A9: 7 | B9: Merchant_007 | C9: food_delivery | D9: East
A10: 8 | B10: Merchant_008 | C10: food_delivery | D10: North
A11: 9 | B11: Merchant_009 | C11: ecommerce | D11: North
A12: 10 | B12: Merchant_010 | C12: grocery | D12: West
A13: 11 | B13: Merchant_011 | C13: ecommerce | D13: North
A14: 12 | B14: Merchant_012 | C14: ecommerce | D14: East
... A42: 40 | B42: Merchant_040 | C42: entertainment | D42: South

Sheet Daily_Merchant_Pivot
A1: Pivot: Sum of amount_inr, filtered to status = "captured", grouped by Date (rows) x merchant_id (columns). Feeds the Merchant Daily Total lookup on Sheet1 via INDEX/MATCH.
A2: Date | B2: 1 | C2: 2 | D2: 3 | E2: 4 | F2: 5 | G2: 6 | H2: 7 | I2: 8 | J2: 9 | K2: 10 | L2: 11 | M2: 12 | N2: 13 | O2: 14 | P2: 15 | Q2: 16 | R2: 17 | S2: 18 | T2: 19 | U2: 20 | V2: 21 | W2: 22 | X2: 23 | Y2: 24 | Z2: 25 | AA2: 26 | AB2: 27 | AC2: 28 | AD2: 29 | AE2: 30 | AF2: 31 | AG2: 32 | AH2: 33 | AI2: 34 | AJ2: 35 | AK2: 36 | AL2: 37 | AM2: 38 | AN2: 39 | AO2: 40
A3: 46023 | B3: =SUMIFS(Master!$F$3:$F$532,Master!$C$3:$C$532,B$2,Master!$E$3:$E$532,">="&$A3,Master!$E$3:$E$532,"<"&($A3+1),Master!$H$3:$H$532,"captured") -> 0 | C3: =SUMIFS(Master!$F$3:$F$532,Master!$C$3:$C$532,C$2,Master!$E$3:$E$532,">="&$A3,Master!$E$3:$E$532,"<"&($A3+1),Master!$H$3:$H$532,"captured") -> 0 | D3: =SUMIFS(Master!$F$3:$F$532,Master!$C$3:$C$532,D$2,Master!$E$3:$E$532,">="&$A3,Master!$E$3:$E$532,"<"&($A3+1),Master!$H$3:$H$532,"captured") -> 0 | E3: =SUMIFS(Master!$F$3:$F$532,Master!$C$3:$C$532,E$2,Master!$E$3:$E$532,">="&$A3,Master!$E$3:$E$532,"<"&($A3+1),Master!$H$3:$H$532,"captured") -> 0 | F3: =SUMIFS(Master!$F$3:$F$532,Master!$C$3:$C$532,F$2,Master!$E$3:$E$532,">="&$A3,Master!$E$3:$E$532,"<"&($A3+1),Master!$H$3:$H$532,"captured") -> 0 | G3: =SUMIFS(Master!$F$3:$F$532,Master!$C$3:$C$532,G$2,Master!$E$3:$E$532,">="&$A3,Master!$E$3:$E$532,"<"&($A3+1),Master!$H$3:$H$532,"captured") -> 149 | H3: =SUMIFS(Master!$F$3:$F$532,Master!$C$3:$C$532,H$2,Master!$E$3:$E$532,">="&$A3,Master!$E$3:$E$532,"<"&($A3+1),Master!$H$3:$H$532,"captured") -> 0 | I3: =SUMIFS(Master!$F$3:$F$532,Master!$C$3:$C$532,I$2,Master!$E$3:$E$532,">="&$A3,Master!$E$3:$E$532,"<"&($A3+1),Master!$H$3:$H$532,"captured") -> 0 | ... AO3: =SUMIFS(Master!$F$3:$F$532,Master!$C$3:$C$532,AO$2,Master!$E$3:$E$532,">="&$A3,Master!$E$3:$E$532,"<"&($A3+1),Master!$H$3:$H$532,"captured") -> 299
A4: 46024 | B4: =SUMIFS(Master!$F$3:$F$532,Master!$C$3:$C$532,B$2,Master!$E$3:$E$532,">="&$A4,Master!$E$3:$E$532,"<"&($A4+1),Master!$H$3:$H$532,"captured") -> 0 | C4: =SUMIFS(Master!$F$3:$F$532,Master!$C$3:$C$532,C$2,Master!$E$3:$E$532,">="&$A4,Master!$E$3:$E$532,"<"&($A4+1),Master!$H$3:$H$532,"captured") -> 0 | D4: =SUMIFS(Master!$F$3:$F$532,Master!$C$3:$C$532,D$2,Master!$E$3:$E$532,">="&$A4,Master!$E$3:$E$532,"<"&($A4+1),Master!$H$3:$H$532,"captured") -> 0 | E4: =SUMIFS(Master!$F$3:$F$532,Master!$C$3:$C$532,E$2,Master!$E$3:$E$532,">="&$A4,Master!$E$3:$E$532,"<"&($A4+1),Master!$H$3:$H$532,"captured") -> 149 | F4: =SUMIFS(Master!$F$3:$F$532,Master!$C$3:$C$532,F$2,Master!$E$3:$E$532,">="&$A4,Master!$E$3:$E$532,"<"&($A4+1),Master!$H$3:$H$532,"captured") -> 0 | G4: =SUMIFS(Master!$F$3:$F$532,Master!$C$3:$C$532,G$2,Master!$E$3:$E$532,">="&$A4,Master!$E$3:$E$532,"<"&($A4+1),Master!$H$3:$H$532,"captured") -> 0 | H4: =SUMIFS(Master!$F$3:$F$532,Master!$C$3:$C$532,H$2,Master!$E$3:$E$532,">="&$A4,Master!$E$3:$E$532,"<"&($A4+1),Master!$H$3:$H$532,"captured") -> 2999 | I4: =SUMIFS(Master!$F$3:$F$532,Master!$C$3:$C$532,I$2,Master!$E$3:$E$532,">="&$A4,Master!$E$3:$E$532,"<"&($A4+1),Master!$H$3:$H$532,"captured") -> 0 | ... AO4: =SUMIFS(Master!$F$3:$F$532,Master!$C$3:$C$532,AO$2,Master!$E$3:$E$532,">="&$A4,Master!$E$3:$E$532,"<"&($A4+1),Master!$H$3:$H$532,"captured") -> 799
A5: 46025 | B5: =SUMIFS(Master!$F$3:$F$532,Master!$C$3:$C$532,B$2,Master!$E$3:$E$532,">="&$A5,Master!$E$3:$E$532,"<"&($A5+1),Master!$H$3:$H$532,"captured") -> 0 | C5: =SUMIFS(Master!$F$3:$F$532,Master!$C$3:$C$532,C$2,Master!$E$3:$E$532,">="&$A5,Master!$E$3:$E$532,"<"&($A5+1),Master!$H$3:$H$532,"captured") -> 0 | D5: =SUMIFS(Master!$F$3:$F$532,Master!$C$3:$C$532,D$2,Master!$E$3:$E$532,">="&$A5,Master!$E$3:$E$532,"<"&($A5+1),Master!$H$3:$H$532,"captured") -> 198 | E5: =SUMIFS(Master!$F$3:$F$532,Master!$C$3:$C$532,E$2,Master!$E$3:$E$532,">="&$A5,Master!$E$3:$E$532,"<"&($A5+1),Master!$H$3:$H$532,"captured") -> 0 | F5: =SUMIFS(Master!$F$3:$F$532,Master!$C$3:$C$532,F$2,Master!$E$3:$E$532,">="&$A5,Master!$E$3:$E$532,"<"&($A5+1),Master!$H$3:$H$532,"captured") -> 499 | G5: =SUMIFS(Master!$F$3:$F$532,Master!$C$3:$C$532,G$2,Master!$E$3:$E$532,">="&$A5,Master!$E$3:$E$532,"<"&($A5+1),Master!$H$3:$H$532,"captured") -> 799 | H5: =SUMIFS(Master!$F$3:$F$532,Master!$C$3:$C$532,H$2,Master!$E$3:$E$532,">="&$A5,Master!$E$3:$E$532,"<"&($A5+1),Master!$H$3:$H$532,"captured") -> 149 | I5: =SUMIFS(Master!$F$3:$F$532,Master!$C$3:$C$532,I$2,Master!$E$3:$E$532,">="&$A5,Master!$E$3:$E$532,"<"&($A5+1),Master!$H$3:$H$532,"captured") -> 299 | ... AO5: =SUMIFS(Master!$F$3:$F$532,Master!$C$3:$C$532,AO$2,Master!$E$3:$E$532,">="&$A5,Master!$E$3:$E$532,"<"&($A5+1),Master!$H$3:$H$532,"captured") -> 49
A6: 46026 | B6: =SUMIFS(Master!$F$3:$F$532,Master!$C$3:$C$532,B$2,Master!$E$3:$E$532,">="&$A6,Master!$E$3:$E$532,"<"&($A6+1),Master!$H$3:$H$532,"captured") -> 0 | C6: =SUMIFS(Master!$F$3:$F$532,Master!$C$3:$C$532,C$2,Master!$E$3:$E$532,">="&$A6,Master!$E$3:$E$532,"<"&($A6+1),Master!$H$3:$H$532,"captured") -> 0 | D6: =SUMIFS(Master!$F$3:$F$532,Master!$C$3:$C$532,D$2,Master!$E$3:$E$532,">="&$A6,Master!$E$3:$E$532,"<"&($A6+1),Master!$H$3:$H$532,"captured") -> 0 | E6: =SUMIFS(Master!$F$3:$F$532,Master!$C$3:$C$532,E$2,Master!$E$3:$E$532,">="&$A6,Master!$E$3:$E$532,"<"&($A6+1),Master!$H$3:$H$532,"captured") -> 0 | F6: =SUMIFS(Master!$F$3:$F$532,Master!$C$3:$C$532,F$2,Master!$E$3:$E$532,">="&$A6,Master!$E$3:$E$532,"<"&($A6+1),Master!$H$3:$H$532,"captured") -> 0 | G6: =SUMIFS(Master!$F$3:$F$532,Master!$C$3:$C$532,G$2,Master!$E$3:$E$532,">="&$A6,Master!$E$3:$E$532,"<"&($A6+1),Master!$H$3:$H$532,"captured") -> 0 | H6: =SUMIFS(Master!$F$3:$F$532,Master!$C$3:$C$532,H$2,Master!$E$3:$E$532,">="&$A6,Master!$E$3:$E$532,"<"&($A6+1),Master!$H$3:$H$532,"captured") -> 0 | I6: =SUMIFS(Master!$F$3:$F$532,Master!$C$3:$C$532,I$2,Master!$E$3:$E$532,">="&$A6,Master!$E$3:$E$532,"<"&($A6+1),Master!$H$3:$H$532,"captured") -> 0 | ... AO6: =SUMIFS(Master!$F$3:$F$532,Master!$C$3:$C$532,AO$2,Master!$E$3:$E$532,">="&$A6,Master!$E$3:$E$532,"<"&($A6+1),Master!$H$3:$H$532,"captured") -> 0
A7: 46027 | B7: =SUMIFS(Master!$F$3:$F$532,Master!$C$3:$C$532,B$2,Master!$E$3:$E$532,">="&$A7,Master!$E$3:$E$532,"<"&($A7+1),Master!$H$3:$H$532,"captured") -> 1499 | C7: =SUMIFS(Master!$F$3:$F$532,Master!$C$3:$C$532,C$2,Master!$E$3:$E$532,">="&$A7,Master!$E$3:$E$532,"<"&($A7+1),Master!$H$3:$H$532,"captured") -> 0 | D7: =SUMIFS(Master!$F$3:$F$532,Master!$C$3:$C$532,D$2,Master!$E$3:$E$532,">="&$A7,Master!$E$3:$E$532,"<"&($A7+1),Master!$H$3:$H$532,"captured") -> 99 | E7: =SUMIFS(Master!$F$3:$F$532,Master!$C$3:$C$532,E$2,Master!$E$3:$E$532,">="&$A7,Master!$E$3:$E$532,"<"&($A7+1),Master!$H$3:$H$532,"captured") -> 0 | F7: =SUMIFS(Master!$F$3:$F$532,Master!$C$3:$C$532,F$2,Master!$E$3:$E$532,">="&$A7,Master!$E$3:$E$532,"<"&($A7+1),Master!$H$3:$H$532,"captured") -> 0 | G7: =SUMIFS(Master!$F$3:$F$532,Master!$C$3:$C$532,G$2,Master!$E$3:$E$532,">="&$A7,Master!$E$3:$E$532,"<"&($A7+1),Master!$H$3:$H$532,"captured") -> 1499 | H7: =SUMIFS(Master!$F$3:$F$532,Master!$C$3:$C$532,H$2,Master!$E$3:$E$532,">="&$A7,Master!$E$3:$E$532,"<"&($A7+1),Master!$H$3:$H$532,"captured") -> 4498 | I7: =SUMIFS(Master!$F$3:$F$532,Master!$C$3:$C$532,I$2,Master!$E$3:$E$532,">="&$A7,Master!$E$3:$E$532,"<"&($A7+1),Master!$H$3:$H$532,"captured") -> 0 | ... AO7: =SUMIFS(Master!$F$3:$F$532,Master!$C$3:$C$532,AO$2,Master!$E$3:$E$532,">="&$A7,Master!$E$3:$E$532,"<"&($A7+1),Master!$H$3:$H$532,"captured") -> 0
A8: 46028 | B8: =SUMIFS(Master!$F$3:$F$532,Master!$C$3:$C$532,B$2,Master!$E$3:$E$532,">="&$A8,Master!$E$3:$E$532,"<"&($A8+1),Master!$H$3:$H$532,"captured") -> 149 | C8: =SUMIFS(Master!$F$3:$F$532,Master!$C$3:$C$532,C$2,Master!$E$3:$E$532,">="&$A8,Master!$E$3:$E$532,"<"&($A8+1),Master!$H$3:$H$532,"captured") -> 0 | D8: =SUMIFS(Master!$F$3:$F$532,Master!$C$3:$C$532,D$2,Master!$E$3:$E$532,">="&$A8,Master!$E$3:$E$532,"<"&($A8+1),Master!$H$3:$H$532,"captured") -> 799 | E8: =SUMIFS(Master!$F$3:$F$532,Master!$C$3:$C$532,E$2,Master!$E$3:$E$532,">="&$A8,Master!$E$3:$E$532,"<"&($A8+1),Master!$H$3:$H$532,"captured") -> 0 | F8: =SUMIFS(Master!$F$3:$F$532,Master!$C$3:$C$532,F$2,Master!$E$3:$E$532,">="&$A8,Master!$E$3:$E$532,"<"&($A8+1),Master!$H$3:$H$532,"captured") -> 0 | G8: =SUMIFS(Master!$F$3:$F$532,Master!$C$3:$C$532,G$2,Master!$E$3:$E$532,">="&$A8,Master!$E$3:$E$532,"<"&($A8+1),Master!$H$3:$H$532,"captured") -> 0 | H8: =SUMIFS(Master!$F$3:$F$532,Master!$C$3:$C$532,H$2,Master!$E$3:$E$532,">="&$A8,Master!$E$3:$E$532,"<"&($A8+1),Master!$H$3:$H$532,"captured") -> 0 | I8: =SUMIFS(Master!$F$3:$F$532,Master!$C$3:$C$532,I$2,Master!$E$3:$E$532,">="&$A8,Master!$E$3:$E$532,"<"&($A8+1),Master!$H$3:$H$532,"captured") -> 0 | ... AO8: =SUMIFS(Master!$F$3:$F$532,Master!$C$3:$C$532,AO$2,Master!$E$3:$E$532,">="&$A8,Master!$E$3:$E$532,"<"&($A8+1),Master!$H$3:$H$532,"captured") -> 0
A9: 46029 | B9: =SUMIFS(Master!$F$3:$F$532,Master!$C$3:$C$532,B$2,Master!$E$3:$E$532,">="&$A9,Master!$E$3:$E$532,"<"&($A9+1),Master!$H$3:$H$532,"captured") -> 0 | C9: =SUMIFS(Master!$F$3:$F$532,Master!$C$3:$C$532,C$2,Master!$E$3:$E$532,">="&$A9,Master!$E$3:$E$532,"<"&($A9+1),Master!$H$3:$H$532,"captured") -> 499 | D9: =SUMIFS(Master!$F$3:$F$532,Master!$C$3:$C$532,D$2,Master!$E$3:$E$532,">="&$A9,Master!$E$3:$E$532,"<"&($A9+1),Master!$H$3:$H$532,"captured") -> 798 | E9: =SUMIFS(Master!$F$3:$F$532,Master!$C$3:$C$532,E$2,Master!$E$3:$E$532,">="&$A9,Master!$E$3:$E$532,"<"&($A9+1),Master!$H$3:$H$532,"captured") -> 0 | F9: =SUMIFS(Master!$F$3:$F$532,Master!$C$3:$C$532,F$2,Master!$E$3:$E$532,">="&$A9,Master!$E$3:$E$532,"<"&($A9+1),Master!$H$3:$H$532,"captured") -> 0 | G9: =SUMIFS(Master!$F$3:$F$532,Master!$C$3:$C$532,G$2,Master!$E$3:$E$532,">="&$A9,Master!$E$3:$E$532,"<"&($A9+1),Master!$H$3:$H$532,"captured") -> 0 | H9: =SUMIFS(Master!$F$3:$F$532,Master!$C$3:$C$532,H$2,Master!$E$3:$E$532,">="&$A9,Master!$E$3:$E$532,"<"&($A9+1),Master!$H$3:$H$532,"captured") -> 0 | I9: =SUMIFS(Master!$F$3:$F$532,Master!$C$3:$C$532,I$2,Master!$E$3:$E$532,">="&$A9,Master!$E$3:$E$532,"<"&($A9+1),Master!$H$3:$H$532,"captured") -> 0 | ... AO9: =SUMIFS(Master!$F$3:$F$532,Master!$C$3:$C$532,AO$2,Master!$E$3:$E$532,">="&$A9,Master!$E$3:$E$532,"<"&($A9+1),Master!$H$3:$H$532,"captured") -> 0
A10: 46030 | B10: =SUMIFS(Master!$F$3:$F$532,Master!$C$3:$C$532,B$2,Master!$E$3:$E$532,">="&$A10,Master!$E$3:$E$532,"<"&($A10+1),Master!$H$3:$H$532,"captured") -> 0 | C10: =SUMIFS(Master!$F$3:$F$532,Master!$C$3:$C$532,C$2,Master!$E$3:$E$532,">="&$A10,Master!$E$3:$E$532,"<"&($A10+1),Master!$H$3:$H$532,"captured") -> 299 | D10: =SUMIFS(Master!$F$3:$F$532,Master!$C$3:$C$532,D$2,Master!$E$3:$E$532,">="&$A10,Master!$E$3:$E$532,"<"&($A10+1),Master!$H$3:$H$532,"captured") -> 149 | E10: =SUMIFS(Master!$F$3:$F$532,Master!$C$3:$C$532,E$2,Master!$E$3:$E$532,">="&$A10,Master!$E$3:$E$532,"<"&($A10+1),Master!$H$3:$H$532,"captured") -> 0 | F10: =SUMIFS(Master!$F$3:$F$532,Master!$C$3:$C$532,F$2,Master!$E$3:$E$532,">="&$A10,Master!$E$3:$E$532,"<"&($A10+1),Master!$H$3:$H$532,"captured") -> 0 | G10: =SUMIFS(Master!$F$3:$F$532,Master!$C$3:$C$532,G$2,Master!$E$3:$E$532,">="&$A10,Master!$E$3:$E$532,"<"&($A10+1),Master!$H$3:$H$532,"captured") -> 149 | H10: =SUMIFS(Master!$F$3:$F$532,Master!$C$3:$C$532,H$2,Master!$E$3:$E$532,">="&$A10,Master!$E$3:$E$532,"<"&($A10+1),Master!$H$3:$H$532,"captured") -> 299 | I10: =SUMIFS(Master!$F$3:$F$532,Master!$C$3:$C$532,I$2,Master!$E$3:$E$532,">="&$A10,Master!$E$3:$E$532,"<"&($A10+1),Master!$H$3:$H$532,"captured") -> 99 | ... AO10: =SUMIFS(Master!$F$3:$F$532,Master!$C$3:$C$532,AO$2,Master!$E$3:$E$532,">="&$A10,Master!$E$3:$E$532,"<"&($A10+1),Master!$H$3:$H$532,"captured") -> 0
A11: 46031 | B11: =SUMIFS(Master!$F$3:$F$532,Master!$C$3:$C$532,B$2,Master!$E$3:$E$532,">="&$A11,Master!$E$3:$E$532,"<"&($A11+1),Master!$H$3:$H$532,"captured") -> 5048 | C11: =SUMIFS(Master!$F$3:$F$532,Master!$C$3:$C$532,C$2,Master!$E$3:$E$532,">="&$A11,Master!$E$3:$E$532,"<"&($A11+1),Master!$H$3:$H$532,"captured") -> 0 | D11: =SUMIFS(Master!$F$3:$F$532,Master!$C$3:$C$532,D$2,Master!$E$3:$E$532,">="&$A11,Master!$E$3:$E$532,"<"&($A11+1),Master!$H$3:$H$532,"captured") -> 0 | E11: =SUMIFS(Master!$F$3:$F$532,Master!$C$3:$C$532,E$2,Master!$E$3:$E$532,">="&$A11,Master!$E$3:$E$532,"<"&($A11+1),Master!$H$3:$H$532,"captured") -> 0 | F11: =SUMIFS(Master!$F$3:$F$532,Master!$C$3:$C$532,F$2,Master!$E$3:$E$532,">="&$A11,Master!$E$3:$E$532,"<"&($A11+1),Master!$H$3:$H$532,"captured") -> 448 | G11: =SUMIFS(Master!$F$3:$F$532,Master!$C$3:$C$532,G$2,Master!$E$3:$E$532,">="&$A11,Master!$E$3:$E$532,"<"&($A11+1),Master!$H$3:$H$532,"captured") -> 99 | H11: =SUMIFS(Master!$F$3:$F$532,Master!$C$3:$C$532,H$2,Master!$E$3:$E$532,">="&$A11,Master!$E$3:$E$532,"<"&($A11+1),Master!$H$3:$H$532,"captured") -> 0 | I11: =SUMIFS(Master!$F$3:$F$532,Master!$C$3:$C$532,I$2,Master!$E$3:$E$532,">="&$A11,Master!$E$3:$E$532,"<"&($A11+1),Master!$H$3:$H$532,"captured") -> 0 | ... AO11: =SUMIFS(Master!$F$3:$F$532,Master!$C$3:$C$532,AO$2,Master!$E$3:$E$532,">="&$A11,Master!$E$3:$E$532,"<"&($A11+1),Master!$H$3:$H$532,"captured") -> 0
A12: 46032 | B12: =SUMIFS(Master!$F$3:$F$532,Master!$C$3:$C$532,B$2,Master!$E$3:$E$532,">="&$A12,Master!$E$3:$E$532,"<"&($A12+1),Master!$H$3:$H$532,"captured") -> 0 | C12: =SUMIFS(Master!$F$3:$F$532,Master!$C$3:$C$532,C$2,Master!$E$3:$E$532,">="&$A12,Master!$E$3:$E$532,"<"&($A12+1),Master!$H$3:$H$532,"captured") -> 0 | D12: =SUMIFS(Master!$F$3:$F$532,Master!$C$3:$C$532,D$2,Master!$E$3:$E$532,">="&$A12,Master!$E$3:$E$532,"<"&($A12+1),Master!$H$3:$H$532,"captured") -> 0 | E12: =SUMIFS(Master!$F$3:$F$532,Master!$C$3:$C$532,E$2,Master!$E$3:$E$532,">="&$A12,Master!$E$3:$E$532,"<"&($A12+1),Master!$H$3:$H$532,"captured") -> 0 | F12: =SUMIFS(Master!$F$3:$F$532,Master!$C$3:$C$532,F$2,Master!$E$3:$E$532,">="&$A12,Master!$E$3:$E$532,"<"&($A12+1),Master!$H$3:$H$532,"captured") -> 99 | G12: =SUMIFS(Master!$F$3:$F$532,Master!$C$3:$C$532,G$2,Master!$E$3:$E$532,">="&$A12,Master!$E$3:$E$532,"<"&($A12+1),Master!$H$3:$H$532,"captured") -> 0 | H12: =SUMIFS(Master!$F$3:$F$532,Master!$C$3:$C$532,H$2,Master!$E$3:$E$532,">="&$A12,Master!$E$3:$E$532,"<"&($A12+1),Master!$H$3:$H$532,"captured") -> 499 | I12: =SUMIFS(Master!$F$3:$F$532,Master!$C$3:$C$532,I$2,Master!$E$3:$E$532,">="&$A12,Master!$E$3:$E$532,"<"&($A12+1),Master!$H$3:$H$532,"captured") -> 0 | ... AO12: =SUMIFS(Master!$F$3:$F$532,Master!$C$3:$C$532,AO$2,Master!$E$3:$E$532,">="&$A12,Master!$E$3:$E$532,"<"&($A12+1),Master!$H$3:$H$532,"captured") -> 0
A13: 46033 | B13: =SUMIFS(Master!$F$3:$F$532,Master!$C$3:$C$532,B$2,Master!$E$3:$E$532,">="&$A13,Master!$E$3:$E$532,"<"&($A13+1),Master!$H$3:$H$532,"captured") -> 0 | C13: =SUMIFS(Master!$F$3:$F$532,Master!$C$3:$C$532,C$2,Master!$E$3:$E$532,">="&$A13,Master!$E$3:$E$532,"<"&($A13+1),Master!$H$3:$H$532,"captured") -> 0 | D13: =SUMIFS(Master!$F$3:$F$532,Master!$C$3:$C$532,D$2,Master!$E$3:$E$532,">="&$A13,Master!$E$3:$E$532,"<"&($A13+1),Master!$H$3:$H$532,"captured") -> 0 | E13: =SUMIFS(Master!$F$3:$F$532,Master!$C$3:$C$532,E$2,Master!$E$3:$E$532,">="&$A13,Master!$E$3:$E$532,"<"&($A13+1),Master!$H$3:$H$532,"captured") -> 0 | F13: =SUMIFS(Master!$F$3:$F$532,Master!$C$3:$C$532,F$2,Master!$E$3:$E$532,">="&$A13,Master!$E$3:$E$532,"<"&($A13+1),Master!$H$3:$H$532,"captured") -> 0 | G13: =SUMIFS(Master!$F$3:$F$532,Master!$C$3:$C$532,G$2,Master!$E$3:$E$532,">="&$A13,Master!$E$3:$E$532,"<"&($A13+1),Master!$H$3:$H$532,"captured") -> 1499 | H13: =SUMIFS(Master!$F$3:$F$532,Master!$C$3:$C$532,H$2,Master!$E$3:$E$532,">="&$A13,Master!$E$3:$E$532,"<"&($A13+1),Master!$H$3:$H$532,"captured") -> 0 | I13: =SUMIFS(Master!$F$3:$F$532,Master!$C$3:$C$532,I$2,Master!$E$3:$E$532,">="&$A13,Master!$E$3:$E$532,"<"&($A13+1),Master!$H$3:$H$532,"captured") -> 149 | ... AO13: =SUMIFS(Master!$F$3:$F$532,Master!$C$3:$C$532,AO$2,Master!$E$3:$E$532,">="&$A13,Master!$E$3:$E$532,"<"&($A13+1),Master!$H$3:$H$532,"captured") -> 0
A14: 46034 | B14: =SUMIFS(Master!$F$3:$F$532,Master!$C$3:$C$532,B$2,Master!$E$3:$E$532,">="&$A14,Master!$E$3:$E$532,"<"&($A14+1),Master!$H$3:$H$532,"captured") -> 149 | C14: =SUMIFS(Master!$F$3:$F$532,Master!$C$3:$C$532,C$2,Master!$E$3:$E$532,">="&$A14,Master!$E$3:$E$532,"<"&($A14+1),Master!$H$3:$H$532,"captured") -> 348 | D14: =SUMIFS(Master!$F$3:$F$532,Master!$C$3:$C$532,D$2,Master!$E$3:$E$532,">="&$A14,Master!$E$3:$E$532,"<"&($A14+1),Master!$H$3:$H$532,"captured") -> 0 | E14: =SUMIFS(Master!$F$3:$F$532,Master!$C$3:$C$532,E$2,Master!$E$3:$E$532,">="&$A14,Master!$E$3:$E$532,"<"&($A14+1),Master!$H$3:$H$532,"captured") -> 49 | F14: =SUMIFS(Master!$F$3:$F$532,Master!$C$3:$C$532,F$2,Master!$E$3:$E$532,">="&$A14,Master!$E$3:$E$532,"<"&($A14+1),Master!$H$3:$H$532,"captured") -> 0 | G14: =SUMIFS(Master!$F$3:$F$532,Master!$C$3:$C$532,G$2,Master!$E$3:$E$532,">="&$A14,Master!$E$3:$E$532,"<"&($A14+1),Master!$H$3:$H$532,"captured") -> 0 | H14: =SUMIFS(Master!$F$3:$F$532,Master!$C$3:$C$532,H$2,Master!$E$3:$E$532,">="&$A14,Master!$E$3:$E$532,"<"&($A14+1),Master!$H$3:$H$532,"captured") -> 0 | I14: =SUMIFS(Master!$F$3:$F$532,Master!$C$3:$C$532,I$2,Master!$E$3:$E$532,">="&$A14,Master!$E$3:$E$532,"<"&($A14+1),Master!$H$3:$H$532,"captured") -> 398 | ... AO14: =SUMIFS(Master!$F$3:$F$532,Master!$C$3:$C$532,AO$2,Master!$E$3:$E$532,">="&$A14,Master!$E$3:$E$532,"<"&($A14+1),Master!$H$3:$H$532,"captured") -> 99
... A32: 46052 | B32: =SUMIFS(Master!$F$3:$F$532,Master!$C$3:$C$532,B$2,Master!$E$3:$E$532,">="&$A32,Master!$E$3:$E$532,"<"&($A32+1),Master!$H$3:$H$532,"captured") -> 0 | C32: =SUMIFS(Master!$F$3:$F$532,Master!$C$3:$C$532,C$2,Master!$E$3:$E$532,">="&$A32,Master!$E$3:$E$532,"<"&($A32+1),Master!$H$3:$H$532,"captured") -> 299 | D32: =SUMIFS(Master!$F$3:$F$532,Master!$C$3:$C$532,D$2,Master!$E$3:$E$532,">="&$A32,Master!$E$3:$E$532,"<"&($A32+1),Master!$H$3:$H$532,"captured") -> 49 | E32: =SUMIFS(Master!$F$3:$F$532,Master!$C$3:$C$532,E$2,Master!$E$3:$E$532,">="&$A32,Master!$E$3:$E$532,"<"&($A32+1),Master!$H$3:$H$532,"captured") -> 0 | F32: =SUMIFS(Master!$F$3:$F$532,Master!$C$3:$C$532,F$2,Master!$E$3:$E$532,">="&$A32,Master!$E$3:$E$532,"<"&($A32+1),Master!$H$3:$H$532,"captured") -> 2999 | G32: =SUMIFS(Master!$F$3:$F$532,Master!$C$3:$C$532,G$2,Master!$E$3:$E$532,">="&$A32,Master!$E$3:$E$532,"<"&($A32+1),Master!$H$3:$H$532,"captured") -> 0 | H32: =SUMIFS(Master!$F$3:$F$532,Master!$C$3:$C$532,H$2,Master!$E$3:$E$532,">="&$A32,Master!$E$3:$E$532,"<"&($A32+1),Master!$H$3:$H$532,"captured") -> 0 | I32: =SUMIFS(Master!$F$3:$F$532,Master!$C$3:$C$532,I$2,Master!$E$3:$E$532,">="&$A32,Master!$E$3:$E$532,"<"&($A32+1),Master!$H$3:$H$532,"captured") -> 99 | ... AO32: =SUMIFS(Master!$F$3:$F$532,Master!$C$3:$C$532,AO$2,Master!$E$3:$E$532,">="&$A32,Master!$E$3:$E$532,"<"&($A32+1),Master!$H$3:$H$532,"captured") -> 499

Sheet Summarising Pivot
A3: Sum of amount_inr | B3: Column Labels
A4: Row Labels | B4: captured | C4: chargeback | D4: failed | E4: (blank) | F4: Grand Total
A5: 1 | B5: 10142 | D5: 299 | F5: 10441
A6: 2 | B6: 2141 | D6: 1499 | F6: 3640
A7: 3 | B7: 2986 | F7: 2986
A8: 4 | B8: 6941 | F8: 6941
A9: 5 | B9: 5440 | D9: 499 | F9: 5939
A10: 6 | B10: 6688 | C10: 799 | D10: 49 | F10: 7536
A11: 7 | B11: 11638 | C11: 1999 | D11: 2297 | F11: 15934
A12: 8 | B12: 7086 | C12: 49 | D12: 299 | F12: 7434
A13: 9 | B13: 3588 | D13: 547 | F13: 4135
A14: 10 | B14: 7639 | C14: 4999 | D14: 399 | F14: 13037
A15: 11 | B15: 8793 | C15: 149 | D15: 1499 | F15: 10441
A16: 12 | B16: 9389 | D16: 998 | F16: 10387
A17: 13 | B17: 11890 | C17: 4999 | D17: 2999 | F17: 19888
A18: 14 | B18: 5790 | D18: 598 | F18: 6388
A19: 15 | B19: 7839 | D19: 399 | F19: 8238
A20: 16 | B20: 10134 | D20: 548 | F20: 10682
A21: 17 | B21: 12439 | D21: 299 | F21: 12738
A22: 18 | B22: 12088 | F22: 12088
A23: 19 | B23: 7239 | C23: 4999 | D23: 99 | F23: 12337
A24: 20 | B24: 4193 | D24: 98 | F24: 4291
A25: 21 | B25: 3887 | D25: 4999 | F25: 8886
A26: 22 | B26: 11336 | D26: 1198 | F26: 12534
A27: 23 | B27: 642 | C27: 1999 | D27: 399 | F27: 3040
A28: 24 | B28: 3139 | C28: 149 | F28: 3288
A29: 25 | B29: 11184 | C29: 2999 | D29: 1499 | F29: 15682
A30: 26 | B30: 3041 | D30: 2197 | F30: 5238
A31: 27 | B31: 10238 | C31: 4047 | D31: 1499 | F31: 15784
A32: 28 | B32: 4493 | C32: 1999 | D32: 2998 | F32: 9490
A33: 29 | B33: 5786 | C33: 998 | D33: 6497 | F33: 13281
A34: 30 | B34: 7384 | D34: 499 | F34: 7883
A35: 31 | B35: 1743 | C35: 49 | D35: 2396 | F35: 4188
A36: 32 | B36: 7539 | C36: 1999 | D36: 3547 | F36: 13085
A37: 33 | B37: 10190 | D37: 149 | F37: 10339
A38: 34 | B38: 9635 | D38: 399 | F38: 10034
A39: 35 | B39: 8688 | D39: 598 | F39: 9286
A40: 36 | B40: 6436 | C40: 999 | F40: 7435
A41: 37 | B41: 13484 | C41: 1999 | D41: 99 | F41: 15582
A42: 38 | B42: 3342 | D42: 598 | F42: 3940
...

Sheet Count Vs Count Unique
A3: Row Labels | B3: Count of transaction_id | C3: StdDev of txn_date
A4: 1 | B4: 9 | C4: 6.7597666
A5: 2 | B5: 10 | C5: 7.6478029
A6: 3 | B6: 14 | C6: 10.097329
A7: 4 | B7: 9 | C7: 7.5498344
A8: 5 | B8: 11 | C8: 8.1128406
A9: 6 | B9: 14 | C9: 8.5793004
A10: 7 | B10: 16 | C10: 9.6194248
A11: 8 | B11: 16 | C11: 8.6245773
A12: 9 | B12: 15 | C12: 8.2155486
A13: 10 | B13: 13 | C13: 5.6839856
A14: 11 | B14: 9 | C14: 9.2706227
A15: 12 | B15: 13 | C15: 9.0998732
... A43: 40 | B43: 15 | C43: 9.1062511
A44: (blank)
A45: Grand Total | B45: 531 | C45: 8.4925483
